Workbook

Sheet Legend
A1: NGFW Master WBS - full TNSR parity + complete VPP 26.06 feature surface
A2: Baseline: VPP 26.06 (released 24 June 2026, 28 new features). TNSR scope from Netgate's published feature documentation. Prepared 2026-09-23.
A4: HOW TO USE THIS WORKBOOK
A5: Assumptions | B5: Every lever lives here: delivery FTE, effective PD per FTE-year, overhead factor, Q1 ramp, project start date. Change these and all other sheets recalculate.
A6: WBS | B6: The 102 work items. Edit ONLY the blue columns: Tier, Net PD, Start Q, End Q, Squad, Status, Owner. Black columns are formulas.
A7: Quarter Plan | B7: Capacity vs planned load per quarter, derived from each item's Start Q..End Q span. Keep utilisation at or below 100%.
A8: Summary | B8: Roll-ups by domain, tier and squad. All SUMIF - no hardcoded totals.
A9: Releases | B9: Release train with gate IDs and measurable acceptance criteria. Net PD per release is derived from the WBS.
A10: Sprints | B10: Sprint-level plan for the first six months. Dates derive from the project start date.
A11: Team | B11: Squads, headcount, hiring month.
A12: CapEx | B12: Lab hardware. Without the month-4 traffic generator no performance number is defensible.
A13: Scenarios | B13: Duration for five scope/team combinations, computed from the tier totals.
A15: COLOUR CONVENTION
A16: Blue text | B16: Hardcoded input - you are expected to edit it.
A17: Black text | B17: Formula - leave it alone.
A18: Green text | B18: Link to another sheet.
A19: Yellow fill | B19: Key assumption.
A21: ESTIMATING BASIS
A22: Unit | B22: Person-day (PD) of a mid-to-senior engineer. Effective working year = 190 PD after holidays, leave, meetings and support duty.
A23: What one PD includes | B23: All nine 'definition of done' conditions: data plane proven by a packet-level test; survives vpp restart and reboot; REST endpoint + OpenAPI + generated client; candidate/commit/rollback with failure paths; UI screen with schema-driven form and live status; en+fa strings; unit/integration/E2E tests; user doc + CLI equivalent; audit entry. Pure coding is about 45% of each number.
A24: Tiers | B24: T1 = needed to sell. T2 = needed for TNSR parity. T3 = complete VPP coverage, low commercial value.
A25: Source of the numbers | B25: Bottom-up expert judgement per domain, calibrated against the published TNSR feature set and the VPP 26.06 plugin inventory. No vendor figures exist for this scope - treat every estimate as an assumption and re-base it after Gate G2 (month 6), when the team's real velocity is measurable.
A27: EXAMPLE ROW (WBS sheet)
A28: D3.4 | D3 | Dynamic Routing | OSPFv2 | T1 | 55 | 5 | 5 | S2 | D3.2 | Not started | B28: ID | Domain | Domain name | Work item | Tier | Net PD | Start Q | End Q | Squad | Depends on | Status

Sheet Assumptions
A1: Assumptions and levers
A2: Blue cells on a yellow fill are inputs. Every other figure in this workbook derives from them.
A4: Lever | B4: Value | C4: Note
A5: Delivery FTE | B5: 14 | C5: Engineers + QA + 50% of the architect. Headcount is 15-16.
A6: Effective PD per FTE per year | B6: 190 | C6: 260 working days minus holidays, leave, meetings and support duty.
A7: Overhead factor on estimates | B7: 1.25 | C7: Management, cross-squad integration and rework. Applied to every net estimate.
A8: Quarters in plan | B8: 12 | C8: 36 months.
A9: Q1 ramp factor | B9: 0.5 | C9: Hiring and onboarding - the first quarter delivers at half capacity.
A10: Project start date | B10: 46296 | C10: Drives every date on the Sprints sheet.
A11: Sprint length (weeks) | B11: 2 | C11: Used by the Sprints sheet.
A12: Ramp-up + stabilisation months | B12: 5 | C12: Calendar time no amount of staffing removes: ~1.5 months lost to hiring and onboarding, ~3.5 months of release stabilisation and gates. Added to every scenario's delivery months.
A13: DERIVED
A14: Capacity per full quarter (PD) | B14: =B5*B6/4 -> 665 | C14: Delivery FTE x PD per year / 4
A15: Total plan capacity (PD) | B15: =B14*(B8-1+B9) -> 7647.5 | C15: 11 full quarters + one ramp quarter
A16: Net scope (PD) | B16: =WBS!F105 -> 5185 | C16: Sum of every WBS item
A17: Loaded scope (PD) | B17: =B16*B7 -> 6481.25 | C17: Net scope x overhead factor
A18: Utilisation of capacity | B18: =IFERROR(B17/B15,0) -> 0.84749918 | C18: Keep below 100% - the remainder is the contingency reserve
A19: Contingency reserve | B19: =1-B18 -> 0.15250082 | C19: Do not spend this on new scope before month 30
A20: Delivery months at full capacity | B20: =IFERROR(B17/(B5*B6/12),0) -> 29.238722 | C20: Excludes ramp-up and release-stabilisation time
A22: Re-base every figure on this sheet after Gate G2 (month 6), when the team's measured velocity replaces judgement.

Sheet WBS
A1: ID | B1: Domain | C1: Domain name | D1: Work item | E1: Tier | F1: Net PD | G1: Loaded PD | H1: Start Q | I1: End Q | J1: Quarters | K1: PD / quarter | L1: Squad | M1: Release | N1: Depends on | O1: Status | P1: Owner | Q1: Notes
A2: D0.1 | B2: D0 | C2: Foundation & Platform | D2: Monorepo, CI/CD, codegen pipeline (Zod -> OpenAPI -> client -> proto -> binapi) | E2: T1 | F2: 25 | G2: =F2*Assumptions!$B$7 -> 31.25 | H2: 1 | I2: 1 | J2: =I2-H2+1 -> 1 | K2: =IFERROR(F2/J2,0) -> 25 | L2: S6 | M2: =IFERROR(INDEX(Releases!$A$5:$A$10,MATCH(I2-1,Releases!$E$5:$E$10,1)),"") -> R0.1 Alpha | O2: Not started | Q2: CI must fail on dirty generated output
A3: D0.2 | B3: D0 | C3: Foundation & Platform | D3: Pinned VPP fork, patch management, VPP package build | E3: T1 | F3: 30 | G3: =F3*Assumptions!$B$7 -> 37.5 | H3: 1 | I3: 2 | J3: =I3-H3+1 -> 2 | K3: =IFERROR(F3/J3,0) -> 15 | L3: S6 | M3: =IFERROR(INDEX(Releases!$A$5:$A$10,MATCH(I3-1,Releases!$E$5:$E$10,1)),"") -> R0.1 Alpha | N3: D0.1 | O3: Not started | Q3: Track a stable release branch, never master
A4: D0.3 | B4: D0 | C4: Foundation & Platform | D4: OS image: Ubuntu 24.04 autoinstall + installer ISO | E4: T1 | F4: 45 | G4: =F4*Assumptions!$B$7 -> 56.25 | H4: 2 | I4: 3 | J4: =I4-H4+1 -> 2 | K4: =IFERROR(F4/J4,0) -> 22.5 | L4: S6 | M4: =IFERROR(INDEX(Releases!$A$5:$A$10,MATCH(I4-1,Releases!$E$5:$E$10,1)),"") -> R0.5 Beta (MVP) | N4: D0.2 | O4: Not started
A5: D0.4 | B5: D0 | C5: Foundation & Platform | D5: Debian packaging, signed APT repository | E5: T1 | F5: 25 | G5: =F5*Assumptions!$B$7 -> 31.25 | H5: 1 | I5: 2 | J5: =I5-H5+1 -> 2 | K5: =IFERROR(F5/J5,0) -> 12.5 | L5: S6 | M5: =IFERROR(INDEX(Releases!$A$5:$A$10,MATCH(I5-1,Releases!$E$5:$E$10,1)),"") -> R0.1 Alpha | N5: D0.1 | O5: Not started
A6: D0.5 | B6: D0 | C6: Foundation & Platform | D6: A/B image upgrade with automatic rollback | E6: T1 | F6: 40 | G6: =F6*Assumptions!$B$7 -> 50 | H6: 6 | I6: 6 | J6: =I6-H6+1 -> 1 | K6: =IFERROR(F6/J6,0) -> 40 | L6: S6 | M6: =IFERROR(INDEX(Releases!$A$5:$A$10,MATCH(I6-1,Releases!$E$5:$E$10,1)),"") -> R1.0 GA-1 | N6: D0.3 | O6: Not started | Q6: Required for GA-1
A7: D0.6 | B7: D0 | C7: Foundation & Platform | D7: startup.conf generator: hugepages, workers, RSS, NUMA, isolcpus, PCI whitelist | E7: T1 | F7: 30 | G7: =F7*Assumptions!$B$7 -> 37.5 | H7: 2 | I7: 2 | J7: =I7-H7+1 -> 1 | K7: =IFERROR(F7/J7,0) -> 30 | L7: S1 | M7: =IFERROR(INDEX(Releases!$A$5:$A$10,MATCH(I7-1,Releases!$E$5:$E$10,1)),"") -> R0.1 Alpha | N7: D0.2 | O7: Not started
A8: D0.7 | B8: D0 | C8: Foundation & Platform | D8: Agent core: govpp connection, stats reader, reconciler/KVScheduler, dependency graph | E8: T1 | F8: 70 | G8: =F8*Assumptions!$B$7 -> 87.5 | H8: 1 | I8: 2 | J8: =I8-H8+1 -> 2 | K8: =IFERROR(F8/J8,0) -> 35 | L8: S1 | M8: =IFERROR(INDEX(Releases!$A$5:$A$10,MATCH(I8-1,Releases!$E$5:$E$10,1)),"") -> R0.1 Alpha | N8: D0.2 | O8: Not started | Q8: CRITICAL PATH - everything depends on this
A9: D0.8 | B9: D0 | C9: Foundation & Platform | D9: API core: NestJS, candidate/running datastore, atomic commit, confirmed-commit, revisions, rollback | E9: T1 | F9: 75 | G9: =F9*Assumptions!$B$7 -> 93.75 | H9: 1 | I9: 2 | J9: =I9-H9+1 -> 2 | K9: =IFERROR(F9/J9,0) -> 37.5 | L9: S4 | M9: =IFERROR(INDEX(Releases!$A$5:$A$10,MATCH(I9-1,Releases!$E$5:$E$10,1)),"") -> R0.1 Alpha | N9: D0.1 | O9: Not started | Q9: CRITICAL PATH
A10: D0.9 | B10: D0 | C10: Foundation & Platform | D10: Auth, RBAC, audit log, API keys, TLS, TPM-backed secret store | E10: T1 | F10: 55 | G10: =F10*Assumptions!$B$7 -> 68.75 | H10: 2 | I10: 2 | J10: =I10-H10+1 -> 1 | K10: =IFERROR(F10/J10,0) -> 55 | L10: S4 | M10: =IFERROR(INDEX(Releases!$A$5:$A$10,MATCH(I10-1,Releases!$E$5:$E$10,1)),"") -> R0.1 Alpha | N10: D0.8 | O10: Not started
A11: D0.10 | B11: D0 | C11: Foundation & Platform | D11: UI shell: theme, layout, i18n en/fa + RTL, SchemaForm renderer, DataGrid wrapper, WS client | E11: T1 | F11: 80 | G11: =F11*Assumptions!$B$7 -> 100 | H11: 1 | I11: 2 | J11: =I11-H11+1 -> 2 | K11: =IFERROR(F11/J11,0) -> 40 | L11: S5 | M11: =IFERROR(INDEX(Releases!$A$5:$A$10,MATCH(I11-1,Releases!$E$5:$E$10,1)),"") -> R0.1 Alpha | N11: D0.8 | O11: Not started
A12: D0.11 | B12: D0 | C12: Foundation & Platform | D12: Interactive CLI (clixon-like: config mode, completion, show commands) | E12: T1 | F12: 90 | G12: =F12*Assumptions!$B$7 -> 112.5 | H12: 6 | I12: 7 | J12: =I12-H12+1 -> 2 | K12: =IFERROR(F12/J12,0) -> 45 | L12: S4 | M12: =IFERROR(INDEX(Releases!$A$5:$A$10,MATCH(I12-1,Releases!$E$5:$E$10,1)),"") -> R1.5 GA-2 | N12: D0.8 | O12: Not started | Q12: TNSR's primary interface
A13: D0.12 | B13: D0 | C13: Foundation & Platform | D13: Telemetry pipeline: stats -> gRPC stream -> WS fan-out -> Prometheus -> history | E13: T1 | F13: 50 | G13: =F13*Assumptions!$B$7 -> 62.5 | H13: 2 | I13: 3 | J13: =I13-H13+1 -> 2 | K13: =IFERROR(F13/J13,0) -> 25 | L13: S4 | M13: =IFERROR(INDEX(Releases!$A$5:$A$10,MATCH(I13-1,Releases!$E$5:$E$10,1)),"") -> R0.5 Beta (MVP) | N13: D0.7 | O13: Not started
A14: D0.13 | B14: D0 | C14: Foundation & Platform | D14: Test infra: containerlab/QEMU lab, Robot Framework, TRex harness, Playwright | E14: T1 | F14: 70 | G14: =F14*Assumptions!$B$7 -> 87.5 | H14: 1 | I14: 2 | J14: =I14-H14+1 -> 2 | K14: =IFERROR(F14/J14,0) -> 35 | L14: QA | M14: =IFERROR(INDEX(Releases!$A$5:$A$10,MATCH(I14-1,Releases!$E$5:$E$10,1)),"") -> R0.1 Alpha | N14: D0.1 | O14: Not started
A15: D1.1 | B15: D1 | C15: Interfaces & L2 | D15: NIC inventory and driver binding: dpdk, rdma, af_xdp, af_packet, vmxnet3, virtio, vhost-user, tap-v2, netmap, memif, pipe, Marvell mGig | E15: T1 | F15: 70 | G15: =F15*Assumptions!$B$7 -> 87.5 | H15: 2 | I15: 3 | J15: =I15-H15+1 -> 2 | K15: =IFERROR(F15/J15,0) -> 35 | L15: S1 | M15: =IFERROR(INDEX(Releases!$A$5:$A$10,MATCH(I15-1,Releases!$E$5:$E$10,1)),"") -> R0.5 Beta (MVP) | N15: D0.6 | O15: Not started | Q15: Fix a supported-hardware matrix; refuse 'any NIC'
A16: D1.2 | B16: D1 | C16: Interfaces & L2 | D16: Interface basics: admin state, MTU, MAC, promisc, rx-mode, rx/tx queues, worker placement | E16: T1 | F16: 35 | G16: =F16*Assumptions!$B$7 -> 43.75 | H16: 2 | I16: 2 | J16: =I16-H16+1 -> 1 | K16: =IFERROR(F16/J16,0) -> 35 | L16: S1 | M16: =IFERROR(INDEX(Releases!$A$5:$A$10,MATCH(I16-1,Releases!$E$5:$E$10,1)),"") -> R0.1 Alpha | N16: D0.7 | O16: Not started
A17: D1.3 | B17: D1 | C17: Interfaces & L2 | D17: IPv4/IPv6 addressing + IP unnumbered | E17: T1 | F17: 20 | G17: =F17*Assumptions!$B$7 -> 25 | H17: 2 | I17: 2 | J17: =I17-H17+1 -> 1 | K17: =IFERROR(F17/J17,0) -> 20 | L17: S1 | M17: =IFERROR(INDEX(Releases!$A$5:$A$10,MATCH(I17-1,Releases!$E$5:$E$10,1)),"") -> R0.1 Alpha | N17: D1.2 | O17: Not started
A18: D1.4 | B18: D1 | C18: Interfaces & L2 | D18: 802.1q sub-interfaces + QinQ/802.1ad stacking | E18: T1 | F18: 25 | G18: =F18*Assumptions!$B$7 -> 31.25 | H18: 2 | I18: 2 | J18: =I18-H18+1 -> 1 | K18: =IFERROR(F18/J18,0) -> 25 | L18: S1 | M18: =IFERROR(INDEX(Releases!$A$5:$A$10,MATCH(I18-1,Releases!$E$5:$E$10,1)),"") -> R0.1 Alpha | N18: D1.2 | O18: Not started
A19: D1.5 | B19: D1 | C19: Interfaces & L2 | D19: Bonding: LACP, XOR, round-robin, active-backup | E19: T1 | F19: 30 | G19: =F19*Assumptions!$B$7 -> 37.5 | H19: 2 | I19: 3 | J19: =I19-H19+1 -> 2 | K19: =IFERROR(F19/J19,0) -> 15 | L19: S1 | M19: =IFERROR(INDEX(Releases!$A$5:$A$10,MATCH(I19-1,Releases!$E$5:$E$10,1)),"") -> R0.5 Beta (MVP) | N19: D1.2 | O19: Not started
A20: D1.6 | B20: D1 | C20: Interfaces & L2 | D20: L2: bridge domains, cross-connect, L2XC, L3XC, split-horizon, MAC aging, time-range MAC filter | E20: T1 | F20: 45 | G20: =F20*Assumptions!$B$7 -> 56.25 | H20: 2 | I20: 3 | J20: =I20-H20+1 -> 2 | K20: =IFERROR(F20/J20,0) -> 22.5 | L20: S1 | M20: =IFERROR(INDEX(Releases!$A$5:$A$10,MATCH(I20-1,Releases!$E$5:$E$10,1)),"") -> R0.5 Beta (MVP) | N20: D1.2 | O20: Not started
A21: D1.7 | B21: D1 | C21: Interfaces & L2 | D21: LLDP | E21: T2 | F21: 12 | G21: =F21*Assumptions!$B$7 -> 15 | H21: 3 | I21: 3 | J21: =I21-H21+1 -> 1 | K21: =IFERROR(F21/J21,0) -> 12 | L21: S1 | M21: =IFERROR(INDEX(Releases!$A$5:$A$10,MATCH(I21-1,Releases!$E$5:$E$10,1)),"") -> R0.5 Beta (MVP) | N21: D1.2 | O21: Not started
A22: D1.8 | B22: D1 | C22: Interfaces & L2 | D22: VNET GSO, checksum offload, jumbo frames | E22: T1 | F22: 20 | G22: =F22*Assumptions!$B$7 -> 25 | H22: 4 | I22: 4 | J22: =I22-H22+1 -> 1 | K22: =IFERROR(F22/J22,0) -> 20 | L22: S1 | M22: =IFERROR(INDEX(Releases!$A$5:$A$10,MATCH(I22-1,Releases!$E$5:$E$10,1)),"") -> R0.5 Beta (MVP) | N22: D1.2 | O22: Not started
A23: D1.9 | B23: D1 | C23: Interfaces & L2 | D23: Network Delay Simulator (nsim) | E23: T3 | F23: 8 | G23: =F23*Assumptions!$B$7 -> 10 | H23: 10 | I23: 10 | J23: =I23-H23+1 -> 1 | K23: =IFERROR(F23/J23,0) -> 8 | L23: S1 | M23: =IFERROR(INDEX(Releases!$A$5:$A$10,MATCH(I23-1,Releases!$E$5:$E$10,1)),"") -> R2.0 GA-3 | N23: D1.2 | O23: Not started | Q23: Test tool, not a product feature
A24: D1.10 | B24: D1 | C24: Interfaces & L2 | D24: SPAN / ERSPAN mirroring | E24: T2 | F24: 25 | G24: =F24*Assumptions!$B$7 -> 31.25 | H24: 7 | I24: 7 | J24: =I24-H24+1 -> 1 | K24: =IFERROR(F24/J24,0) -> 25 | L24: S1 | M24: =IFERROR(INDEX(Releases!$A$5:$A$10,MATCH(I24-1,Releases!$E$5:$E$10,1)),"") -> R1.5 GA-2 | N24: D1.6 | O24: Not started
A25: D1.11 | B25: D1 | C25: Interfaces & L2 | D25: Loopback / BVI interfaces | E25: T1 | F25: 10 | G25: =F25*Assumptions!$B$7 -> 12.5 | H25: 3 | I25: 3 | J25: =I25-H25+1 -> 1 | K25: =IFERROR(F25/J25,0) -> 10 | L25: S1 | M25: =IFERROR(INDEX(Releases!$A$5:$A$10,MATCH(I25-1,Releases!$E$5:$E$10,1)),"") -> R0.5 Beta (MVP) | N25: D1.6 | O25: Not started
A26: D2.1 | B26: D2 | C26: L3, MPLS & Multicast | D26: VRF/table management + Source VRF Select | E26: T1 | F26: 30 | G26: =F26*Assumptions!$B$7 -> 37.5 | H26: 3 | I26: 3 | J26: =I26-H26+1 -> 1 | K26: =IFERROR(F26/J26,0) -> 30 | L26: S2 | M26: =IFERROR(INDEX(Releases!$A$5:$A$10,MATCH(I26-1,Releases!$E$5:$E$10,1)),"") -> R0.5 Beta (MVP) | N26: D1.3 | O26: Not started
A27: D2.2 | B27: D2 | C27: L3, MPLS & Multicast | D27: Static routes v4/v6, ECMP, weighted paths, DPO/adjacency view | E27: T1 | F27: 35 | G27: =F27*Assumptions!$B$7 -> 43.75 | H27: 3 | I27: 3 | J27: =I27-H27+1 -> 1 | K27: =IFERROR(F27/J27,0) -> 35 | L27: S2 | M27: =IFERROR(INDEX(Releases!$A$5:$A$10,MATCH(I27-1,Releases!$E$5:$E$10,1)),"") -> R0.5 Beta (MVP) | N27: D2.1 | O27: Not started
A28: D2.3 | B28: D2 | C28: L3, MPLS & Multicast | D28: Neighbour DB: ARP, ND, proxy-ND, IPv6 RA, IPv6 DAD (new in 26.06) | E28: T1 | F28: 30 | G28: =F28*Assumptions!$B$7 -> 37.5 | H28: 3 | I28: 3 | J28: =I28-H28+1 -> 1 | K28: =IFERROR(F28/J28,0) -> 30 | L28: S1 | M28: =IFERROR(INDEX(Releases!$A$5:$A$10,MATCH(I28-1,Releases!$E$5:$E$10,1)),"") -> R0.5 Beta (MVP) | N28: D1.3 | O28: Not started
A29: D2.4 | B29: D2 | C29: L3, MPLS & Multicast | D29: RPF strict/loose, ADL allow/deny lists, Auto-SDL | E29: T2 | F29: 30 | G29: =F29*Assumptions!$B$7 -> 37.5 | H29: 9 | I29: 9 | J29: =I29-H29+1 -> 1 | K29: =IFERROR(F29/J29,0) -> 30 | L29: S2 | M29: =IFERROR(INDEX(Releases!$A$5:$A$10,MATCH(I29-1,Releases!$E$5:$E$10,1)),"") -> R2.0 GA-3 | N29: D2.2 | O29: Not started
A30: D2.5 | B30: D2 | C30: L3, MPLS & Multicast | D30: FIB browser with server-side pagination (1M+ routes) | E30: T1 | F30: 25 | G30: =F30*Assumptions!$B$7 -> 31.25 | H30: 3 | I30: 4 | J30: =I30-H30+1 -> 2 | K30: =IFERROR(F30/J30,0) -> 12.5 | L30: S5 | M30: =IFERROR(INDEX(Releases!$A$5:$A$10,MATCH(I30-1,Releases!$E$5:$E$10,1)),"") -> R0.5 Beta (MVP) | N30: D2.2 | O30: Not started
A31: D2.6 | B31: D2 | C31: L3, MPLS & Multicast | D31: Tools: ping, traceroute, ARP flush | E31: T1 | F31: 20 | G31: =F31*Assumptions!$B$7 -> 25 | H31: 3 | I31: 3 | J31: =I31-H31+1 -> 1 | K31: =IFERROR(F31/J31,0) -> 20 | L31: S4 | M31: =IFERROR(INDEX(Releases!$A$5:$A$10,MATCH(I31-1,Releases!$E$5:$E$10,1)),"") -> R0.5 Beta (MVP) | N31: D2.2 | O31: Not started
A32: D2.7 | B32: D2 | C32: L3, MPLS & Multicast | D32: Classifier/classify tables, IP session redirect, ACL-Based Forwarding (PBR) | E32: T2 | F32: 45 | G32: =F32*Assumptions!$B$7 -> 56.25 | H32: 5 | I32: 5 | J32: =I32-H32+1 -> 1 | K32: =IFERROR(F32/J32,0) -> 45 | L32: S2 | M32: =IFERROR(INDEX(Releases!$A$5:$A$10,MATCH(I32-1,Releases!$E$5:$E$10,1)),"") -> R1.0 GA-1 | N32: D2.2 | O32: Not started
A33: D2.8 | B33: D2 | C33: L3, MPLS & Multicast | D33: MPLS: label operations, LSP, MPLS-over-Ethernet, basic L3VPN, SR-MPLS | E33: T2 | F33: 90 | G33: =F33*Assumptions!$B$7 -> 112.5 | H33: 9 | I33: 10 | J33: =I33-H33+1 -> 2 | K33: =IFERROR(F33/J33,0) -> 45 | L33: S2 | M33: =IFERROR(INDEX(Releases!$A$5:$A$10,MATCH(I33-1,Releases!$E$5:$E$10,1)),"") -> R2.0 GA-3 | N33: D3.3 | O33: Not started
A34: D2.9 | B34: D2 | C34: L3, MPLS & Multicast | D34: Multicast: IGMPv3, PIM via FRR, mfib, BIER | E34: T3 | F34: 70 | G34: =F34*Assumptions!$B$7 -> 87.5 | H34: 9 | I34: 10 | J34: =I34-H34+1 -> 2 | K34: =IFERROR(F34/J34,0) -> 35 | L34: S2 | M34: =IFERROR(INDEX(Releases!$A$5:$A$10,MATCH(I34-1,Releases!$E$5:$E$10,1)),"") -> R2.0 GA-3 | N34: D3.2 | O34: Not started | Q34: BIER has near-zero commercial demand
A35: D3.1 | B35: D3 | C35: Dynamic Routing | D35: linux-cp / linux-nl hardening: interface pairs, state/MTU sync, VRF mapping, IPv6, full-table performance | E35: T1 | F35: 90 | G35: =F35*Assumptions!$B$7 -> 112.5 | H35: 3 | I35: 4 | J35: =I35-H35+1 -> 2 | K35: =IFERROR(F35/J35,0) -> 45 | L35: S2 | M35: =IFERROR(INDEX(Releases!$A$5:$A$10,MATCH(I35-1,Releases!$E$5:$E$10,1)),"") -> R0.5 Beta (MVP) | N35: D1.2 | O35: Not started | Q35: CRITICAL PATH - prototype in Q3, not Q5
A36: D3.2 | B36: D3 | C36: Dynamic Routing | D36: FRR lifecycle: renderer framework, JSON state readers, safe reload, dry-run | E36: T1 | F36: 60 | G36: =F36*Assumptions!$B$7 -> 75 | H36: 4 | I36: 4 | J36: =I36-H36+1 -> 1 | K36: =IFERROR(F36/J36,0) -> 60 | L36: S2 | M36: =IFERROR(INDEX(Releases!$A$5:$A$10,MATCH(I36-1,Releases!$E$5:$E$10,1)),"") -> R0.5 Beta (MVP) | N36: D3.1 | O36: Not started
A37: D3.3 | B37: D3 | C37: Dynamic Routing | D37: BGP: core, AFI/SAFI v4/v6, communities, route-maps, prefix-lists, AS-path filters, peer-groups, RR, confederation, graceful restart, BGP Roles (RFC 9234), add-path, VPNv4/VPNv6 | E37: T1 | F37: 140 | G37: =F37*Assumptions!$B$7 -> 175 | H37: 4 | I37: 5 | J37: =I37-H37+1 -> 2 | K37: =IFERROR(F37/J37,0) -> 70 | L37: S2 | M37: =IFERROR(INDEX(Releases!$A$5:$A$10,MATCH(I37-1,Releases!$E$5:$E$10,1)),"") -> R1.0 GA-1 | N37: D3.2 | O37: Not started
A38: D3.4 | B38: D3 | C38: Dynamic Routing | D38: OSPFv2 | E38: T1 | F38: 55 | G38: =F38*Assumptions!$B$7 -> 68.75 | H38: 5 | I38: 5 | J38: =I38-H38+1 -> 1 | K38: =IFERROR(F38/J38,0) -> 55 | L38: S2 | M38: =IFERROR(INDEX(Releases!$A$5:$A$10,MATCH(I38-1,Releases!$E$5:$E$10,1)),"") -> R1.0 GA-1 | N38: D3.2 | O38: Not started
A39: D3.5 | B39: D3 | C39: Dynamic Routing | D39: OSPFv3 | E39: T2 | F39: 40 | G39: =F39*Assumptions!$B$7 -> 50 | H39: 8 | I39: 8 | J39: =I39-H39+1 -> 1 | K39: =IFERROR(F39/J39,0) -> 40 | L39: S2 | M39: =IFERROR(INDEX(Releases!$A$5:$A$10,MATCH(I39-1,Releases!$E$5:$E$10,1)),"") -> R1.5 GA-2 | N39: D3.2 | O39: Not started
A40: D3.6 | B40: D3 | C40: Dynamic Routing | D40: IS-IS | E40: T2 | F40: 45 | G40: =F40*Assumptions!$B$7 -> 56.25 | H40: 7 | I40: 7 | J40: =I40-H40+1 -> 1 | K40: =IFERROR(F40/J40,0) -> 45 | L40: S2 | M40: =IFERROR(INDEX(Releases!$A$5:$A$10,MATCH(I40-1,Releases!$E$5:$E$10,1)),"") -> R1.5 GA-2 | N40: D3.2 | O40: Not started
...

Sheet Quarter Plan
A1: Quarter plan - capacity versus planned load
A2: Each item's effort is spread evenly across its Start Q..End Q span. Utilisation above 100% means the quarter is overcommitted.
A4: Q | B4: Label | C4: Months | D4: Ramp | E4: Capacity PD | F4: Planned net PD | G4: Planned loaded PD | H4: Utilisation | I4: Milestone / gate
A5: 1 | B5: Q1 | C5: M1-M3 | D5: =IF($A5=1,Assumptions!$B$9,1) -> 0.5 | E5: =Assumptions!$B$14*D5 -> 332.5 | F5: =SUMPRODUCT((WBS!$H$2:$H$103<=$A5)*(WBS!$I$2:$I$103>=$A5)*WBS!$K$2:$K$103) -> 200 | G5: =F5*Assumptions!$B$7 -> 250 | H5: =IFERROR(G5/E5,0) -> 0.7518797 | I5: G1 - first vertical slice on real hardware
A6: 2 | B6: Q2 | C6: M4-M6 | D6: =IF($A6=1,Assumptions!$B$9,1) -> 1 | E6: =Assumptions!$B$14*D6 -> 665 | F6: =SUMPRODUCT((WBS!$H$2:$H$103<=$A6)*(WBS!$I$2:$I$103>=$A6)*WBS!$K$2:$K$103) -> 460 | G6: =F6*Assumptions!$B$7 -> 575 | H6: =IFERROR(G6/E6,0) -> 0.86466165 | I6: G2 = R0.1 Alpha
A7: 3 | B7: Q3 | C7: M7-M9 | D7: =IF($A7=1,Assumptions!$B$9,1) -> 1 | E7: =Assumptions!$B$14*D7 -> 665 | F7: =SUMPRODUCT((WBS!$H$2:$H$103<=$A7)*(WBS!$I$2:$I$103>=$A7)*WBS!$K$2:$K$103) -> 504.5 | G7: =F7*Assumptions!$B$7 -> 630.625 | H7: =IFERROR(G7/E7,0) -> 0.94830827 | I7: G3 - IPsec interop with strongSwan/FortiGate/Cisco
A8: 4 | B8: Q4 | C8: M10-M12 | D8: =IF($A8=1,Assumptions!$B$9,1) -> 1 | E8: =Assumptions!$B$14*D8 -> 665 | F8: =SUMPRODUCT((WBS!$H$2:$H$103<=$A8)*(WBS!$I$2:$I$103>=$A8)*WBS!$K$2:$K$103) -> 510.27778 | G8: =F8*Assumptions!$B$7 -> 637.84722 | H8: =IFERROR(G8/E8,0) -> 0.95916876 | I8: G4 = R0.5 Beta (MVP), first customer PoC
A9: 5 | B9: Q5 | C9: M13-M15 | D9: =IF($A9=1,Assumptions!$B$9,1) -> 1 | E9: =Assumptions!$B$14*D9 -> 665 | F9: =SUMPRODUCT((WBS!$H$2:$H$103<=$A9)*(WBS!$I$2:$I$103>=$A9)*WBS!$K$2:$K$103) -> 527.77778 | G9: =F9*Assumptions!$B$7 -> 659.72222 | H9: =IFERROR(G9/E9,0) -> 0.99206349 | I9: BGP + OSPFv2 + BFD + full ACL
A10: 6 | B10: Q6 | C10: M16-M18 | D10: =IF($A10=1,Assumptions!$B$9,1) -> 1 | E10: =Assumptions!$B$14*D10 -> 665 | F10: =SUMPRODUCT((WBS!$H$2:$H$103<=$A10)*(WBS!$I$2:$I$103>=$A10)*WBS!$K$2:$K$103) -> 475.27778 | G10: =F10*Assumptions!$B$7 -> 594.09722 | H10: =IFERROR(G10/E10,0) -> 0.89337928 | I10: G5 = R1.0 GA-1
A11: 7 | B11: Q7 | C11: M19-M21 | D11: =IF($A11=1,Assumptions!$B$9,1) -> 1 | E11: =Assumptions!$B$14*D11 -> 665 | F11: =SUMPRODUCT((WBS!$H$2:$H$103<=$A11)*(WBS!$I$2:$I$103>=$A11)*WBS!$K$2:$K$103) -> 522.77778 | G11: =F11*Assumptions!$B$7 -> 653.47222 | H11: =IFERROR(G11/E11,0) -> 0.982665 | I11: CGNAT, QoS, PKI, WireGuard, IS-IS
A12: 8 | B12: Q8 | C12: M22-M24 | D12: =IF($A12=1,Assumptions!$B$9,1) -> 1 | E12: =Assumptions!$B$14*D12 -> 665 | F12: =SUMPRODUCT((WBS!$H$2:$H$103<=$A12)*(WBS!$I$2:$I$103>=$A12)*WBS!$K$2:$K$103) -> 540.27778 | G12: =F12*Assumptions!$B$7 -> 675.34722 | H12: =IFERROR(G12/E12,0) -> 1.0155597 | I12: HA state sync, RESTCONF, IPFIX, AAA
A13: 9 | B13: Q9 | C13: M25-M27 | D13: =IF($A13=1,Assumptions!$B$9,1) -> 1 | E13: =Assumptions!$B$14*D13 -> 665 | F13: =SUMPRODUCT((WBS!$H$2:$H$103<=$A13)*(WBS!$I$2:$I$103>=$A13)*WBS!$K$2:$K$103) -> 422.77778 | G13: =F13*Assumptions!$B$7 -> 528.47222 | H13: =IFERROR(G13/E13,0) -> 0.79469507 | I13: G6 = R1.5 GA-2 (full TNSR parity), MPLS/multicast start
A14: 10 | B14: Q10 | C14: M28-M30 | D14: =IF($A14=1,Assumptions!$B$9,1) -> 1 | E14: =Assumptions!$B$14*D14 -> 665 | F14: =SUMPRODUCT((WBS!$H$2:$H$103<=$A14)*(WBS!$I$2:$I$103>=$A14)*WBS!$K$2:$K$103) -> 525.77778 | G14: =F14*Assumptions!$B$7 -> 657.22222 | H14: =IFERROR(G14/E14,0) -> 0.98830409 | I14: G7 = R2.0 GA-3 (complete VPP surface)
A15: 11 | B15: Q11 | C15: M31-M33 | D15: =IF($A15=1,Assumptions!$B$9,1) -> 1 | E15: =Assumptions!$B$14*D15 -> 665 | F15: =SUMPRODUCT((WBS!$H$2:$H$103<=$A15)*(WBS!$I$2:$I$103>=$A15)*WBS!$K$2:$K$103) -> 347.77778 | G15: =F15*Assumptions!$B$7 -> 434.72222 | H15: =IFERROR(G15/E15,0) -> 0.65371763 | I15: Hardening, licensing, documentation
A16: 12 | B16: Q12 | C16: M34-M36 | D16: =IF($A16=1,Assumptions!$B$9,1) -> 1 | E16: =Assumptions!$B$14*D16 -> 665 | F16: =SUMPRODUCT((WBS!$H$2:$H$103<=$A16)*(WBS!$I$2:$I$103>=$A16)*WBS!$K$2:$K$103) -> 147.77778 | G16: =F16*Assumptions!$B$7 -> 184.72222 | H16: =IFERROR(G16/E16,0) -> 0.27777778 | I16: G8 = R2.5 GA-Final
C17: TOTAL | E17: =SUM(E5:E16) -> 7647.5 | F17: =SUM(F5:F16) -> 5185 | G17: =SUM(G5:G16) -> 6481.25 | H17: =IFERROR(G17/E17,0) -> 0.84749918
A19: FINDING: balancing the 102 items against quarterly capacity pushes eight Tier-2 items past Q8 - remote-access VPN, AAA, Terraform/Ansible/SDK, native IKEv2, RPF/ADL, syslog and log explorer, support bundle, and the virtualisation images.
A21: Full TNSR parity therefore completes at the end of Q9 = month 27, not month 24. Three options: (a) accept month 27; (b) add 2 FTE in Q7-Q8 (about USD 120k) and hold month 24; (c) cut those eight items from GA-2 into R2.0. Decide deliberately now rather than discovering it in month 23.
A23: The gap between total capacity and planned load is the programme's contingency reserve. Do not spend it on new scope before month 30.

Sheet Summary
A1: Roll-ups
A2: Every figure is a SUMIF over the WBS sheet. Nothing here is hardcoded.
A4: Domain | B4: Domain name | C4: Net PD | D4: Loaded PD | E4: Share of net
A5: D0 | B5: Foundation & Platform | C5: =SUMIF(WBS!$B$2:$B$103,$A5,WBS!$F$2:$F$103) -> 685 | D5: =C5*Assumptions!$B$7 -> 856.25 | E5: =IFERROR(C5/$C$18,0) -> 0.13211186
A6: D1 | B6: Interfaces & L2 | C6: =SUMIF(WBS!$B$2:$B$103,$A6,WBS!$F$2:$F$103) -> 300 | D6: =C6*Assumptions!$B$7 -> 375 | E6: =IFERROR(C6/$C$18,0) -> 0.057859209
A7: D2 | B7: L3, MPLS & Multicast | C7: =SUMIF(WBS!$B$2:$B$103,$A7,WBS!$F$2:$F$103) -> 375 | D7: =C7*Assumptions!$B$7 -> 468.75 | E7: =IFERROR(C7/$C$18,0) -> 0.072324012
A8: D3 | B8: Dynamic Routing | C8: =SUMIF(WBS!$B$2:$B$103,$A8,WBS!$F$2:$F$103) -> 540 | D8: =C8*Assumptions!$B$7 -> 675 | E8: =IFERROR(C8/$C$18,0) -> 0.10414658
A9: D4 | B9: NAT & CGNAT | C9: =SUMIF(WBS!$B$2:$B$103,$A9,WBS!$F$2:$F$103) -> 365 | D9: =C9*Assumptions!$B$7 -> 456.25 | E9: =IFERROR(C9/$C$18,0) -> 0.070395371
A10: D5 | B10: Firewall & ACL | C10: =SUMIF(WBS!$B$2:$B$103,$A10,WBS!$F$2:$F$103) -> 270 | D10: =C10*Assumptions!$B$7 -> 337.5 | E10: =IFERROR(C10/$C$18,0) -> 0.052073288
A11: D6 | B11: VPN & Tunnels | C11: =SUMIF(WBS!$B$2:$B$103,$A11,WBS!$F$2:$F$103) -> 650 | D11: =C11*Assumptions!$B$7 -> 812.5 | E11: =IFERROR(C11/$C$18,0) -> 0.12536162
A12: D7 | B12: Services, QoS & Host Stack | C12: =SUMIF(WBS!$B$2:$B$103,$A12,WBS!$F$2:$F$103) -> 575 | D12: =C12*Assumptions!$B$7 -> 718.75 | E12: =IFERROR(C12/$C$18,0) -> 0.11089682
A13: D8 | B13: Observability & Ops | C13: =SUMIF(WBS!$B$2:$B$103,$A13,WBS!$F$2:$F$103) -> 425 | D13: =C13*Assumptions!$B$7 -> 531.25 | E13: =IFERROR(C13/$C$18,0) -> 0.081967213
A14: D9 | B14: High Availability | C14: =SUMIF(WBS!$B$2:$B$103,$A14,WBS!$F$2:$F$103) -> 210 | D14: =C14*Assumptions!$B$7 -> 262.5 | E14: =IFERROR(C14/$C$18,0) -> 0.040501446
A15: D10 | B15: Multi-tenancy & AAA | C15: =SUMIF(WBS!$B$2:$B$103,$A15,WBS!$F$2:$F$103) -> 125 | D15: =C15*Assumptions!$B$7 -> 156.25 | E15: =IFERROR(C15/$C$18,0) -> 0.024108004
A16: D11 | B16: Cloud & Virtualization | C16: =SUMIF(WBS!$B$2:$B$103,$A16,WBS!$F$2:$F$103) -> 130 | D16: =C16*Assumptions!$B$7 -> 162.5 | E16: =IFERROR(C16/$C$18,0) -> 0.025072324
A17: D12 | B17: Hardening, QA, Docs & Release | C17: =SUMIF(WBS!$B$2:$B$103,$A17,WBS!$F$2:$F$103) -> 535 | D17: =C17*Assumptions!$B$7 -> 668.75 | E17: =IFERROR(C17/$C$18,0) -> 0.10318226
B18: TOTAL | C18: =SUM(C5:C17) -> 5185 | D18: =SUM(D5:D17) -> 6481.25
A20: Tier | B20: Meaning | C20: Net PD | D20: Loaded PD | E20: Share | F20: Duration at plan FTE (months)
A21: T1 | B21: Needed to sell | C21: =SUMIF(WBS!$E$2:$E$103,$A21,WBS!$F$2:$F$103) -> 3345 | D21: =C21*Assumptions!$B$7 -> 4181.25 | E21: =IFERROR(C21/$C$24,0) -> 0.64513018 | F21: =IFERROR(D21/(Assumptions!$B$5*Assumptions!$B$6/12),0) -> 18.862782
A22: T2 | B22: Needed for TNSR parity | C22: =SUMIF(WBS!$E$2:$E$103,$A22,WBS!$F$2:$F$103) -> 1427 | D22: =C22*Assumptions!$B$7 -> 1783.75 | E22: =IFERROR(C22/$C$24,0) -> 0.27521697 | F22: =IFERROR(D22/(Assumptions!$B$5*Assumptions!$B$6/12),0) -> 8.0469925
A23: T3 | B23: Complete VPP coverage, low value | C23: =SUMIF(WBS!$E$2:$E$103,$A23,WBS!$F$2:$F$103) -> 413 | D23: =C23*Assumptions!$B$7 -> 516.25 | E23: =IFERROR(C23/$C$24,0) -> 0.079652845 | F23: =IFERROR(D23/(Assumptions!$B$5*Assumptions!$B$6/12),0) -> 2.3289474
B24: TOTAL | C24: =SUM(C21:C23) -> 5185 | D24: =SUM(D21:D23) -> 6481.25
A26: Squad | B26: Squad name | C26: Net PD | D26: Loaded PD | E26: Share of net
A27: S1 | B27: Dataplane & Agent | C27: =SUMIF(WBS!$L$2:$L$103,$A27,WBS!$F$2:$F$103) -> 860 | D27: =C27*Assumptions!$B$7 -> 1075 | E27: =IFERROR(C27/WBS!$F$105,0) -> 0.16586307
A28: S2 | B28: Routing & L3 | C28: =SUMIF(WBS!$L$2:$L$103,$A28,WBS!$F$2:$F$103) -> 840 | D28: =C28*Assumptions!$B$7 -> 1050 | E28: =IFERROR(C28/WBS!$F$105,0) -> 0.16200579
A29: S3 | B29: Security & VPN | C29: =SUMIF(WBS!$L$2:$L$103,$A29,WBS!$F$2:$F$103) -> 1200 | D29: =C29*Assumptions!$B$7 -> 1500 | E29: =IFERROR(C29/WBS!$F$105,0) -> 0.23143684
A30: S4 | B30: Control Plane | C30: =SUMIF(WBS!$L$2:$L$103,$A30,WBS!$F$2:$F$103) -> 1065 | D30: =C30*Assumptions!$B$7 -> 1331.25 | E30: =IFERROR(C30/WBS!$F$105,0) -> 0.20540019
A31: S5 | B31: Frontend | C31: =SUMIF(WBS!$L$2:$L$103,$A31,WBS!$F$2:$F$103) -> 310 | D31: =C31*Assumptions!$B$7 -> 387.5 | E31: =IFERROR(C31/WBS!$F$105,0) -> 0.05978785
A32: S6 | B32: Platform & Release | C32: =SUMIF(WBS!$L$2:$L$103,$A32,WBS!$F$2:$F$103) -> 435 | D32: =C32*Assumptions!$B$7 -> 543.75 | E32: =IFERROR(C32/WBS!$F$105,0) -> 0.083895853
A33: QA | B33: QA / Lab | C33: =SUMIF(WBS!$L$2:$L$103,$A33,WBS!$F$2:$F$103) -> 355 | D33: =C33*Assumptions!$B$7 -> 443.75 | E33: =IFERROR(C33/WBS!$F$105,0) -> 0.068466731
A34: Writer | B34: Technical writer | C34: =SUMIF(WBS!$L$2:$L$103,$A34,WBS!$F$2:$F$103) -> 120 | D34: =C34*Assumptions!$B$7 -> 150 | E34: =IFERROR(C34/WBS!$F$105,0) -> 0.023143684
B35: TOTAL | C35: =SUM(C27:C34) -> 5185 | D35: =SUM(D27:D34) -> 6481.25
A37: CAUTION: the Squad column names the OWNING squad only. Every item's PD includes the API, UI, test and doc work the nine DoD conditions require, so these totals are not staffing loads - do not size a squad from them.
A38: For real staffing, split each item's PD across squads in a separate effort-allocation model, or add per-squad PD columns to the WBS sheet.

Sheet Releases
A1: Release train and gate acceptance criteria
A2: Net PD per release is derived from each WBS item's End Q. 'Lookup key' drives the Release formula on the WBS sheet - do not reorder or delete these rows.
A4: Release | B4: Target month | C4: Gate | D4: Through Q | E4: Lookup key | F4: Scope added | G4: Measurable acceptance criteria | H4: Net PD
A5: R0.1 Alpha | B5: 6 | C5: G2 | D5: 2 | E5: 0 | F5: Foundation, interfaces/L2, live telemetry | G5: 10 Mpps/core IPv4 @64B; kill -9 vpp rebuilds config <30s; UI counters == vppctl | H5: =SUMIF(WBS!$M$2:$M$103,$A5,WBS!$F$2:$F$103) -> 540
A6: R0.5 Beta (MVP) | B6: 10 | C6: G4 | D6: 4 | E6: 2 | F6: L3/static/VRF, basic NAT44, IPsec S2S, DHCP/DNS/NTP | G6: Customer PoC passed; 100k NAT sessions; commit/rollback with no outage | H6: =SUMIF(WBS!$M$2:$M$103,$A6,WBS!$F$2:$F$103) -> 877
A7: R1.0 GA-1 | B7: 16 | C7: G5 | D7: 6 | E7: 4 | F7: BGP/OSPF/BFD, full ACL and NAT, VRRP, SNMP, backup and upgrade | G7: 1M-route BGP converges <90s; BFD failover <300ms; 100k ACL rules <2% pps loss; IPsec >=20 Gbps | H7: =SUMIF(WBS!$M$2:$M$103,$A7,WBS!$F$2:$F$103) -> 1070
A8: R1.5 GA-2 | B8: 27 | C8: G6 | D8: 8 | E8: 6 | F8: IS-IS/OSPFv3/RIP, CGNAT/MAP, WireGuard, PKI, QoS, IPFIX/sFlow, RESTCONF, HA state sync, AAA | G8: 100% TNSR feature matrix signed off; VRRP failover <1s with sessions preserved; >=100 Gbps on 16 workers | H8: =SUMIF(WBS!$M$2:$M$103,$A8,WBS!$F$2:$F$103) -> 1165
A9: R2.0 GA-3 | B9: 30 | C9: G7 | D9: 10 | E9: 8 | F9: MPLS/SR-MPLS, multicast/BIER, SRv6, LISP, host stack/QUIC/HTTP3, load balancer, multi-tenancy, cloud | G9: Every VPP 26.06 plugin exposed or recorded in a justified out-of-scope list | H9: =SUMIF(WBS!$M$2:$M$103,$A9,WBS!$F$2:$F$103) -> 708
A10: R2.5 GA-Final | B10: 36 | C10: G8 | D10: 12 | E10: 10 | F10: Hardening, secure boot, licensing, offline updates, pen test, 72h soak, full docs, certification | G10: Zero crashes/leaks over 72h at line rate; clean pen test; signed offline bundle; complete SBOM | H10: =SUMIF(WBS!$M$2:$M$103,$A10,WBS!$F$2:$F$103) -> 825
G11: TOTAL | H11: =SUM(H5:H10) -> 5185
A13: G1 (month 3) is an internal gate with no release: unattended bare-metal install under 15 minutes, login, NIC inventory, survives reboot.
A14: G3 (month 9): IPsec tunnel up against strongSwan, FortiGate and Cisco peers; three-router static topology forwards traffic.

Sheet Sprints
A1: Sprint plan - first six months
A2: Dates derive from the project start date and sprint length on the Assumptions sheet. Beyond sprint 12, plan one quarter ahead - sprint detail further out is fiction.
A4: Sprint | B4: Start | C4: End | D4: Deliverable (must be demonstrable) | E4: Gate
A5: S01 | B5: =Assumptions!$B$10+(1-1)*7*Assumptions!$B$11 -> 46296 | C5: =B5+7*Assumptions!$B$11-1 -> 46309 | D5: Monorepo + green CI + automated QEMU box: Ubuntu 24.04, VPP 26.06, two virtio interfaces bound to VPP
A6: S02 | B6: =Assumptions!$B$10+(2-1)*7*Assumptions!$B$11 -> 46310 | C6: =B6+7*Assumptions!$B$11-1 -> 46323 | D6: ngfw-agent connects via govpp, Retrieve() dumps interfaces, one gRPC RPC over a unix socket
A7: S03 | B7: =Assumptions!$B$10+(3-1)*7*Assumptions!$B$11 -> 46324 | C7: =B7+7*Assumptions!$B$11-1 -> 46337 | D7: ngfw-api: GET /api/v1/state/interfaces; schema package with Zod; codegen chain (OpenAPI + client)
A8: S04 | B8: =Assumptions!$B$10+(4-1)*7*Assumptions!$B$11 -> 46338 | C8: =B8+7*Assumptions!$B$11-1 -> 46351 | D8: React interface list with live counters over WebSocket -> FULL VERTICAL SLICE PROVEN
A9: S05 | B9: =Assumptions!$B$10+(5-1)*7*Assumptions!$B$11 -> 46352 | C9: =B9+7*Assumptions!$B$11-1 -> 46365 | D9: Reconciler core: Descriptor + dependency graph + diff/plan/apply; candidate/running datastore; first atomic commit on MTU
A10: S06 | B10: =Assumptions!$B$10+(6-1)*7*Assumptions!$B$11 -> 46366 | C10: =B10+7*Assumptions!$B$11-1 -> 46379 | D10: .deb build + signed APT repo; install on bare metal | E10: G1
A11: S07 | B11: =Assumptions!$B$10+(7-1)*7*Assumptions!$B$11 -> 46380 | C11: =B11+7*Assumptions!$B$11-1 -> 46393 | D11: DPDK driver binding from the UI; NIC inventory; startup.conf generator (hugepages/workers/RSS)
A12: S08 | B12: =Assumptions!$B$10+(8-1)*7*Assumptions!$B$11 -> 46394 | C12: =B12+7*Assumptions!$B$11-1 -> 46407 | D12: v4/v6 addressing, MTU, MAC, rx-queue placement; confirmed-commit with auto-revert timer
A13: S09 | B13: =Assumptions!$B$10+(9-1)*7*Assumptions!$B$11 -> 46408 | C13: =B13+7*Assumptions!$B$11-1 -> 46421 | D13: 802.1q and QinQ sub-interfaces; pending-change bar + diff viewer in the UI
A14: S10 | B14: =Assumptions!$B$10+(10-1)*7*Assumptions!$B$11 -> 46422 | C14: =B14+7*Assumptions!$B$11-1 -> 46435 | D14: Bonding/LACP; bridge domains and L2XC; RBAC + audit + API keys
A15: S11 | B15: =Assumptions!$B$10+(11-1)*7*Assumptions!$B$11 -> 46436 | C15: =B15+7*Assumptions!$B$11-1 -> 46449 | D15: GSO/checksum offload/jumbo; loopback/BVI; LLDP; autoinstall ISO
A16: S12 | B16: =Assumptions!$B$10+(12-1)*7*Assumptions!$B$11 -> 46450 | C16: =B16+7*Assumptions!$B$11-1 -> 46463 | D16: kill -9 vpp in nightly CI; TRex baseline | E16: G2 = R0.1 Alpha
A18: Sprint 4 is the checkpoint that matters: a full vertical slice (VPP -> Go agent -> gRPC -> Node API -> React with live counters) proves the whole architecture in six weeks. If it slips, re-plan before writing more features.

Sheet Team
A1: Team structure and hiring plan
A2: The capacity math on the Assumptions sheet uses delivery FTE, not raw headcount.
A4: Squad | B4: Name | C4: Headcount | D4: Hire by | E4: Responsibility | F4: Key skills
A5: S1 | B5: Dataplane & Agent | C5: 3 | D5: M1 | E5: VPP plugins, govpp, reconciler, renderers, stats | F5: C, Go, DPDK, VPP internals
A6: S2 | B6: Routing & L3 | C6: 2 | D6: M1 | E6: linux-cp, FRR, BGP/OSPF/IS-IS, MPLS, multicast, FIB | F6: Go, network engineering (CCIE/JNCIE)
A7: S3 | B7: Security & VPN | C7: 2 | D7: M6 | E7: IPsec, strongSwan, PKI, WireGuard, NAT, ACL | F7: Go, cryptography, IKE
A8: S4 | B8: Control Plane | C8: 2 | D8: M1 | E8: NestJS, commit engine, RBAC, telemetry, RESTCONF, SDKs | F8: Node.js, TypeScript
A9: S5 | B9: Frontend | C9: 2 | D9: M1 | E9: React/MUI, SchemaForm, dashboards, i18n/RTL | F9: React, TypeScript, UX
A10: S6 | B10: Platform & Release | C10: 1 | D10: M1 | E10: VPP build, packaging, images, APT, upgrade, CI | F10: DevOps, Debian packaging
A11: QA | B11: QA / Lab | C11: 2 | D11: M3 | E11: Robot Framework, TRex, interop, nightly, perf CI | F11: Network test automation
A12: Arch | B12: Architect / TPM | C12: 1 | D12: M0 | E12: Architecture, review, planning (50% delivery) | F12: -
A13: Writer | B13: Technical writer | C13: 0.5 | D13: M12 | E13: User docs, CLI/API reference | F13: -
B14: TOTAL HEADCOUNT | C14: =SUM(C5:C13) -> 15.5
A16: The binding constraint is one senior VPP/DPDK engineer. Start recruiting before month 0 - that hire, not this plan, decides the schedule.
A17: Hiring order: M0 architect + senior VPP engineer | M1 2xGo, 2xNode, 1xReact, 1xDevOps | M3 1xReact, 1xQA | M6 1xGo, 1x senior network engineer, 1xQA/perf | M12 technical writer.

Sheet CapEx
A1: Lab capital expenditure
A2: A performance claim without a traffic generator is marketing fiction. The month-4 purchase is not optional.
A4: Month | B4: Items | C4: Cost (USD) | D4: Cumulative (USD)
A5: M0 | B5: 2 lab servers (single socket, AES-NI, AVX2) + Intel XXV710 25G NICs + 25G switch | C5: 40000 | D5: =SUM($C$5:C5) -> 40000
A6: M4 | B6: TRex traffic generator box + Intel E810 100G NICs - no performance claim is defensible without it | C6: 35000 | D6: =SUM($C$5:C6) -> 75000
A7: M10 | B7: HA pair + second switch + ConnectX-6 for the rdma driver path | C7: 30000 | D7: =SUM($C$5:C7) -> 105000
A8: M18 | B8: 100G switch + optics + Intel QAT card for crypto offload | C8: 35000 | D8: =SUM($C$5:C8) -> 140000
A9: M24 | B9: Interop gear: used Cisco/Juniper router, FortiGate unit | C9: 25000 | D9: =SUM($C$5:C9) -> 165000
B10: TOTAL | C10: =SUM(C5:C9) -> 165000
A12: Order-of-magnitude estimates for used and current-generation COTS hardware as at September 2026. Obtain live quotes before budgeting.

Sheet Scenarios
A1: Scope and staffing scenarios
A2: Delivery months = loaded PD / (FTE x PD-per-year / 12). Total months adds the ramp-up and stabilisation allowance from the Assumptions sheet - calendar time that does not compress by adding people.
A4: Scenario | B4: Scope | C4: Net PD | D4: Loaded PD | E4: Delivery FTE | F4: Delivery months | G4: Total months | H4: Risk assessment
A5: A Aggressive | B5: All (T1+T2+T3) | C5: =Summary!$C$24 -> 5185 | D5: =C5*Assumptions!$B$7 -> 6481.25 | E5: 22 | F5: =IFERROR(D5/(E5*Assumptions!$B$6/12),0) -> 18.606459 | G5: =ROUND(F5+Assumptions!$B$12,0) -> 24 | H5: Critical path does not parallelize; coordination overhead rises about 15%; hiring 22 VPP-capable engineers is unrealistic in most markets.
A6: B Recommended | B6: All (T1+T2+T3) | C6: =Summary!$C$24 -> 5185 | D6: =C6*Assumptions!$B$7 -> 6481.25 | E6: 14 | F6: =IFERROR(D6/(E6*Assumptions!$B$6/12),0) -> 29.238722 | G6: =ROUND(F6+Assumptions!$B$12,0) -> 34 | H6: Balanced. This is the plan in this workbook.
A7: C Lean | B7: All (T1+T2+T3) | C7: =Summary!$C$24 -> 5185 | D7: =C7*Assumptions!$B$7 -> 6481.25 | E7: 10 | F7: =IFERROR(D7/(E7*Assumptions!$B$6/12),0) -> 40.934211 | G7: =ROUND(F7+Assumptions!$B$12,0) -> 46 | H7: Falls behind the VPP release cadence and market timing; the VPP rebase cost recurs every four months.
A8: D Smart | B8: Tier 1 only | C8: =SUMIF(WBS!$E$2:$E$103,"T1",WBS!$F$2:$F$103) -> 3345 | D8: =C8*Assumptions!$B$7 -> 4181.25 | E8: 14 | F8: =IFERROR(D8/(E8*Assumptions!$B$6/12),0) -> 18.862782 | G8: =ROUND(F8+Assumptions!$B$12,0) -> 24 | H8: LOWEST RISK, BEST RETURN. A sellable product with every critical capability; revenue funds T2 and T3.
A9: E TNSR parity | B9: Tier 1 + Tier 2 | C9: =SUMIF(WBS!$E$2:$E$103,"T1",WBS!$F$2:$F$103)+SUMIF(WBS!$E$2:$E$103,"T2",WBS!$F$2:$F$103) -> 4772 | D9: =C9*Assumptions!$B$7 -> 5965 | E9: 14 | F9: =IFERROR(D9/(E9*Assumptions!$B$6/12),0) -> 26.909774 | G9: =ROUND(F9+Assumptions!$B$12,0) -> 32 | H9: Balanced; drops only the 8% of scope that no router customer requests.
A11: Scenario A's figure assumes perfect parallelism, which the critical path (reconciler core -> linux-cp -> BGP) forbids. Treat it as a floor, not a plan.
A13: Scenario B computes to 34 months while the plan on the Quarter Plan sheet runs 12 quarters = 36 months. The two extra months are deliberate planning slack; do not remove them to make a date.
